Workbook

Sheet Sheet1
A1: 번호 | B1: 식별번호 | C1: 초본주소 | D1: 신고연도 | E1: 신고사유 | F1: 이격거리 | G1: 위도 | H1: 경도 | J1: 피해자번호(식별ID)
A2: 10001 | B2: 1 | C2: 경기도 김포군 대곶면 거물대리 212 | D2: 1977 | E2: 신규등록 | F2: 0.57984975 | G2: 126.59935 | H2: 37.668619 | J2: 16-1-0001 | K2: =VLOOKUP(J2, Sheet3!$A$1:$C$470, 2, FALSE) -> 1
A3: 10002 | B3: 1 | C3: 경기도 김포군 대곶면 거물대리 187 | D3: 1985 | E3: 전입 | F3: 0.41856991 | G3: 126.59949 | H3: 37.666233 | J3: 16-1-0001 | K3: =VLOOKUP(J3, Sheet3!$A$1:$C$470, 2, FALSE) -> 1
A4: 10003 | B4: 1 | C4: 경기도 김포군 대곶면 거물대리 187 | D4: 1996 | E4: 명칭변경 | F4: 0.41856991 | G4: 126.59949 | H4: 37.666233 | J4: 16-1-0001 | K4: =VLOOKUP(J4, Sheet3!$A$1:$C$470, 2, FALSE) -> 1
A5: 10004 | B5: 1 | C5: 경기도 김포시 대곶면 거물대리 187 | D5: 1998 | E5: 행정구역변경 | F5: 0.41856991 | G5: 126.59949 | H5: 37.666233 | J5: 16-1-0001 | K5: =VLOOKUP(J5, Sheet3!$A$1:$C$470, 2, FALSE) -> 1
A6: 10005 | B6: 1 | C6: 경기도 김포시 대곶면 거물대리 187 | D6: 2004 | E6: 세대주변경 | F6: 0.41856991 | G6: 126.59949 | H6: 37.666233 | J6: 16-1-0001 | K6: =VLOOKUP(J6, Sheet3!$A$1:$C$470, 2, FALSE) -> 1
A7: 10006 | B7: 1 | C7: 경기도 김포시 대곶면 율마로194번길 62-18 | D7: 2011 | E7: 도로명주소 | F7: 0.41409516 | G7: 126.59945 | H7: 37.666214 | J7: 16-1-0001 | K7: =VLOOKUP(J7, Sheet3!$A$1:$C$470, 2, FALSE) -> 1
A8: 10007 | B8: 1 | C8: 경기도 김포시 대곶면 율마로194번길 62-18 | D8: 2012 | E8: 세대분가 | F8: 0.41409516 | G8: 126.59945 | H8: 37.666214 | J8: 16-1-0001 | K8: =VLOOKUP(J8, Sheet3!$A$1:$C$470, 2, FALSE) -> 1
A9: 10008 | B9: 1 | C9: 경기도 김포시 대곶면 율마로194번길 62-18 | D9: 2012 | E9: 세대합가 | F9: 0.41409516 | G9: 126.59945 | H9: 37.666214 | J9: 16-1-0001 | K9: =VLOOKUP(J9, Sheet3!$A$1:$C$470, 2, FALSE) -> 1
A10: 10009 | B10: 2 | C10: 전라남도 완도군 금일면 월송리 791 | E10: 출생등록 | F10: 371.0744 | G10: 127.05179 | H10: 34.340904 | J10: 16-1-0002 | K10: =VLOOKUP(J10, Sheet3!$A$1:$C$470, 2, FALSE) -> 2
A11: 10010 | B11: 2 | C11: 전라남도 완도군 금일읍 월송리 791 | D11: 1980 | E11: 행정구역변경 | F11: 371.0744 | G11: 127.05179 | H11: 34.340904 | J11: 16-1-0002 | K11: =VLOOKUP(J11, Sheet3!$A$1:$C$470, 2, FALSE) -> 2
A12: 10011 | B12: 2 | C12: 전라남도 곡성군 곡성읍 죽동리 6 | D12: 1997 | E12: 전입 | F12: 271.99284 | G12: 127.28671 | H12: 35.277869 | J12: 16-1-0002 | K12: =VLOOKUP(J12, Sheet3!$A$1:$C$470, 2, FALSE) -> 2
A13: 10012 | B13: 2 | C13: 전라남도 곡성군 곡성읍 죽동리 6 | D13: 1997 | E13: 세대주성명정정 | F13: 271.99284 | G13: 127.28671 | H13: 35.277869 | J13: 16-1-0002 | K13: =VLOOKUP(J13, Sheet3!$A$1:$C$470, 2, FALSE) -> 2
A14: 10013 | B14: 2 | C14: 광주광역시 남구 주월동 1269-10 | D14: 1998 | E14: 전입 | F14: 282.44376 | G14: 126.90569 | H14: 35.131613 | J14: 16-1-0002 | K14: =VLOOKUP(J14, Sheet3!$A$1:$C$470, 2, FALSE) -> 2
A15: 10014 | B15: 2 | C15: 경기도 김포시 대곶면 율생리 470-3 | D15: 1999 | E15: 전입 | F15: 1.6281999 | G15: 126.58189 | H15: 37.654418 | J15: 16-1-0002 | K15: =VLOOKUP(J15, Sheet3!$A$1:$C$470, 2, FALSE) -> 2
A16: 10015 | B16: 2 | C16: 경기도 김포시 대곶면 율생리 529-10 | D16: 2000 | E16: 전입 | F16: 2.0897408 | G16: 126.5811 | H16: 37.649435 | J16: 16-1-0002 | K16: =VLOOKUP(J16, Sheet3!$A$1:$C$470, 2, FALSE) -> 2
A17: 10016 | B17: 2 | C17: 경기도 김포시 대곶면 율생리 529-10 | D17: 2001 | E17: 공동주택변경 | F17: 2.0897408 | G17: 126.5811 | H17: 37.649435 | J17: 16-1-0002 | K17: =VLOOKUP(J17, Sheet3!$A$1:$C$470, 2, FALSE) -> 2
A18: 10017 | B18: 2 | C18: 경기도 김포시 대곶면 율생리 529-10 | D18: 2001 | E18: 전입 | F18: 2.0897408 | G18: 126.5811 | H18: 37.649435 | J18: 16-1-0002 | K18: =VLOOKUP(J18, Sheet3!$A$1:$C$470, 2, FALSE) -> 2
A19: 10018 | B19: 2 | C19: 경기도 김포시 대곶면 율생리 529-10 | D19: 2001 | E19: 전입 | F19: 2.0897408 | G19: 126.5811 | H19: 37.649435 | J19: 16-1-0002 | K19: =VLOOKUP(J19, Sheet3!$A$1:$C$470, 2, FALSE) -> 2
A20: 10019 | B20: 2 | C20: 경기도 김포시 대곶면 거물대리 187 | D20: 2003 | E20: 전입 | F20: 0.41856991 | G20: 126.59949 | H20: 37.666233 | J20: 16-1-0002 | K20: =VLOOKUP(J20, Sheet3!$A$1:$C$470, 2, FALSE) -> 2
A21: 10020 | B21: 2 | C21: 경기도 김포시 대곶면 거물대리 187 | D21: 2003 | E21: 호적신고에의한정리 | F21: 0.41856991 | G21: 126.59949 | H21: 37.666233 | J21: 16-1-0002 | K21: =VLOOKUP(J21, Sheet3!$A$1:$C$470, 2, FALSE) -> 2
A22: 10021 | B22: 2 | C22: 경기도 김포시 대곶면 거물대리 187 | D22: 2004 | E22: 세대주변경 | F22: 0.41856991 | G22: 126.59949 | H22: 37.666233 | J22: 16-1-0002 | K22: =VLOOKUP(J22, Sheet3!$A$1:$C$470, 2, FALSE) -> 2
... A173: 10172 | B173: 270 | C173: 경기도 김포시 대곶면 율마로152번길 115 | D173: 2011 | E173: 도로명주소 | F173: 0.75027778 | G173: 126.60377 | H173: 37.664418 | J173: 20-1-0012 | K173: =VLOOKUP(J173, Sheet3!$A$1:$C$470, 2, FALSE) -> 270
A174: 10173 | B174: 271 | C174: 전라남도 보성군 율어면 유신리 869 | E174: 전입 | F174: 313.87862 | G174: 127.22959 | H174: 34.882875 | J174: 20-1-0013 | K174: =VLOOKUP(J174, Sheet3!$A$1:$C$470, 2, FALSE) -> 271
A175: 10174 | B175: 271 | C175: 경기도 김포군 대곳면 거물대리 474 | D175: 1979 | E175: 전입 | F175: 0.17881817 | G175: 126.59332 | H175: 37.66406 | J175: 20-1-0013 | K175: =VLOOKUP(J175, Sheet3!$A$1:$C$470, 2, FALSE) -> 271
A176: 10175 | B176: 271 | C176: 경기도 김포군 대곳면 거물대리 459 | D176: 1987 | E176: 세대주변경 | F176: 0.074954934 | G176: 126.59466 | H176: 37.664049 | J176: 20-1-0013 | K176: =VLOOKUP(J176, Sheet3!$A$1:$C$470, 2, FALSE) -> 271
A177: 10176 | B177: 271 | C177: 경기도 김포군 대곳면 거물대리 474 | D177: 1987 | E177: 전입 | F177: 0.17881817 | G177: 126.59332 | H177: 37.66406 | J177: 20-1-0013 | K177: =VLOOKUP(J177, Sheet3!$A$1:$C$470, 2, FALSE) -> 271
A178: 10177 | B178: 271 | C178: 경기도 김포군 대곳면 거물대리 409 | D178: 1990 | E178: 전입 | F178: 0.17303184 | G178: 126.59694 | H178: 37.665337 | J178: 20-1-0013 | K178: =VLOOKUP(J178, Sheet3!$A$1:$C$470, 2, FALSE) -> 271
A179: 10178 | B179: 271 | C179: 경기도 김포군 대곶면 거물대리 409 | D179: 1996 | E179: 명칭변경 | F179: 0.17303184 | G179: 126.59694 | H179: 37.665337 | J179: 20-1-0013 | K179: =VLOOKUP(J179, Sheet3!$A$1:$C$470, 2, FALSE) -> 271
A180: 10179 | B180: 271 | C180: 경기도 김포시 대곶면 거물대리 409 | D180: 1998 | E180: 행정구역변경 | F180: 0.17303184 | G180: 126.59694 | H180: 37.665337 | J180: 20-1-0013 | K180: =VLOOKUP(J180, Sheet3!$A$1:$C$470, 2, FALSE) -> 271
A181: 10180 | B181: 271 | C181: 경기도 김포시 대곶면 율마로 161 | D181: 2011 | E181: 도로명주소 | F181: 0.20629002 | G181: 126.59707 | H181: 37.665708 | J181: 20-1-0013 | K181: =VLOOKUP(J181, Sheet3!$A$1:$C$470, 2, FALSE) -> 271
A182: 10181 | B182: 272 | C182: 경기도 김포군 대곳면 거물대리 459 | D182: 1968 | E182: - | F182: 0.074954934 | G182: 126.59466 | H182: 37.664049 | J182: 20-1-0014 | K182: =VLOOKUP(J182, Sheet3!$A$1:$C$470, 2, FALSE) -> 272
A183: 10182 | B183: 272 | C183: 경기도 김포군 대곳면 거물대리 474 | D183: 1987 | E183: 전입 | F183: 0.17881817 | G183: 126.59332 | H183: 37.66406 | J183: 20-1-0014 | K183: =VLOOKUP(J183, Sheet3!$A$1:$C$470, 2, FALSE) -> 272
A184: 10183 | B184: 272 | C184: 경기도 김포군 대곳면 거물대리 409 | D184: 1990 | E184: 전입 | F184: 0.17303184 | G184: 126.59694 | H184: 37.665337 | J184: 20-1-0014 | K184: =VLOOKUP(J184, Sheet3!$A$1:$C$470, 2, FALSE) -> 272
A185: 10184 | B185: 272 | C185: 경기도 김포군 대곶면 거물대리 409 | D185: 1996 | E185: 명칭변경 | F185: 0.17303184 | G185: 126.59694 | H185: 37.665337 | J185: 20-1-0014 | K185: =VLOOKUP(J185, Sheet3!$A$1:$C$470, 2, FALSE) -> 272
A186: 10185 | B186: 272 | C186: 경기도 김포시 대곶면 거물대리 409 | D186: 1998 | E186: 행정구역변경 | F186: 0.17303184 | G186: 126.59694 | H186: 37.665337 | J186: 20-1-0014 | K186: =VLOOKUP(J186, Sheet3!$A$1:$C$470, 2, FALSE) -> 272
... A277: 10276 | B277: 7 | C277: 경기도 김포시 대곶면 율마로256번길 166 | D277: 2016 | E277: 전입 | F277: 1.0634524 | G277: 126.60498 | H277: 37.67019 | J277: 16-1-0007 | K277: =VLOOKUP(J277, Sheet3!$A$1:$C$470, 2, FALSE) -> 7
A278: 10277 | B278: 8 | C278: 경기도 강화군 선원면 연리 394 | E278: 전입 | F278: 8.7641941 | G278: 126.50908 | H278: 37.703812 | J278: 16-1-0008 | K278: =VLOOKUP(J278, Sheet3!$A$1:$C$470, 2, FALSE) -> 8
A279: 10278 | B279: 8 | C279: 경기도 김포군 대곳면 거물대리 29 | D279: 1980 | E279: 전입 | F279: 0.74520969 | G279: 126.59963 | H279: 37.670271 | J279: 16-1-0008 | K279: =VLOOKUP(J279, Sheet3!$A$1:$C$470, 2, FALSE) -> 8
A280: 10279 | B280: 8 | C280: 경기도 김포군 대곳면 거물대리 29 | D280: 1987 | E280: 세대주변경 | F280: 0.74520969 | G280: 126.59963 | H280: 37.670271 | J280: 16-1-0008 | K280: =VLOOKUP(J280, Sheet3!$A$1:$C$470, 2, FALSE) -> 8
...

Sheet Sheet3
A1: 16-1-0001 | B1: 1 | C1: 최해진
A2: 16-1-0002 | B2: 2 | C2: 구미숙
A3: 16-1-0003 | B3: 3 | C3: 김만식
A4: 16-1-0004 | B4: 4 | C4: 배중호
A5: 16-1-0005 | B5: 5 | C5: 이명순
A6: 16-1-0006 | B6: 6 | C6: 간규섭
A7: 16-1-0007 | B7: 7 | C7: 간왕춘
A8: 16-1-0008 | B8: 8 | C8: 윤문숙
A9: 16-1-0009 | B9: 9 | C9: 이효재
A10: 16-1-0010 | B10: 10 | C10: 백미숙
A11: 16-1-0011 | B11: 11 | C11: 유춘자
A12: 16-1-0012 | B12: 12 | C12: 윤영희
... A470: 23-1-0005 | B470: 1157 | C470: 이순신

Sheet Sheet2
A1: 피해자번호(식별ID) | B1: 거주기간 | C1: 피해지역
A2: 16-1-0001
A3: 16-1-0002
A4: 16-1-0003
A5: 16-1-0004
A6: 16-1-0005
A7: 16-1-0006
A8: 17-2-0223
A9: 17-2-0224
A10: 20-1-0001
A11: 20-1-0002
A12: 20-1-0003
A13: 20-1-0004
... A442: 17-1-0013
